<?xml version='1.0'?>
<sdf version="1.4">
  <model name="wheel_robot_simple">
    <link name="body_link">
      <pose>-0.10 0 0.1 0 0 0</pose>
      <inertial>
        <mass>5.0</mass>
        <inertia>
          <ixx>0.042</ixx>
          <ixy>0.0</ixy>
          <ixz>0.0</ixz>
          <iyy>0.071</iyy>
          <iyz>0.0</iyz>
          <izz>0.104</izz>
        </inertia>
      </inertial>
      <collision name="collision">
        <geometry>
          <box>
            <size>0.4 0.3 0.1</size>
          </box>
        </geometry>
      </collision>
      <visual name="visual">
        <geometry>
          <box>
            <size>0.4 0.3 0.1</size>
          </box>
        </geometry>
      </visual>
    </link>

    <joint name='back_ball_joint' type='fixed'>
      <parent>body_link</parent>
      <child>back_ball_link</child>
      <pose>0 0 0 0 0 0</pose>
      <axis>
        <use_parent_model_frame>true</use_parent_model_frame>
        <xyz>-0.23 0 0.05</xyz>
      </axis>
    </joint>
    <link name="back_ball_link">
      <pose>-0.23 0 0.05 0 0 0</pose>
      <inertial>
        <mass>0.1</mass>
        <inertia>
          <ixx>0.0001</ixx>
          <ixy>0.0</ixy>
          <ixz>0.0</ixz>
          <iyy>0.0001</iyy>
          <iyz>0.0</iyz>
          <izz>0.0001</izz>
        </inertia>
      </inertial>
      <collision name="collision">
        <geometry>
          <sphere>
            <radius>0.05</radius>
          </sphere>
        </geometry>
        <surface>
          <friction>
            <ode>
              <mu>0.1</mu>
              <mu2>0.1</mu2>
            </ode>
          </friction>
          <contact>
            <ode>
              <kp>200000</kp>
              <kd>1</kd>
            </ode>
          </contact>
        </surface>
      </collision>
      <visual name="visual">
        <geometry>
          <sphere>
            <radius>0.05</radius>
          </sphere>
        </geometry>
      </visual>
    </link>

    <joint name='left_wheel_joint' type='revolute'>
      <parent>body_link</parent>
      <child>left_wheel_link</child>
      <pose>0 0 0 0 0 0</pose>
      <axis>
        <xyz>0 1 0</xyz>
      </axis>
    </joint>
    <link name="left_wheel_link">
      <pose>0 0.18 0.072 1.5707 0 0</pose>
      <inertial>
        <mass>0.2</mass>
        <inertia>
          <ixx>0.00026</ixx>
          <ixy>0.0</ixy>
          <ixz>0.0</ixz>
          <iyy>0.00026</iyy>
          <iyz>0.0</iyz>
          <izz>0.00052</izz>
        </inertia>
      </inertial>
      <collision name="collision">
        <geometry>
          <cylinder>
            <radius>0.072</radius>
            <length>0.04</length>
          </cylinder>
        </geometry>
        <surface>
          <friction>
            <ode>
              <mu>0.5</mu>
              <mu2>0.5</mu2>
            </ode>
          </friction>
          <contact>
            <ode>
              <kp>100000</kp>
              <kd>1</kd>
            </ode>
          </contact>
        </surface>
      </collision>
      <visual name="visual">
        <geometry>
          <cylinder>
            <radius>0.072</radius>
            <length>0.04</length>
          </cylinder>
        </geometry>
        <material>
          <script>
            <uri>file://media/materials/scripts/gazebo.material</uri>
            <name>Gazebo/Red</name>
          </script>
        </material>
      </visual>
    </link>

    <joint name='right_wheel_joint' type='revolute'>
      <parent>body_link</parent>
      <child>right_wheel_link</child>
      <pose>0 0 0 0 0 0</pose>
      <axis>
        <xyz>0 1 0</xyz>
      </axis>
    </joint>
    <link name="right_wheel_link">
      <pose>0 -0.18 0.072 1.5707 0 0</pose>
      <inertial>
        <mass>0.2</mass>
        <inertia>
          <ixx>0.00026</ixx>
          <ixy>0.0</ixy>
          <ixz>0.0</ixz>
          <iyy>0.00026</iyy>
          <iyz>0.0</iyz>
          <izz>0.00052</izz>
        </inertia>
      </inertial>
      <collision name="collision">
        <geometry>
          <cylinder>
            <radius>0.072</radius>
            <length>0.04</length>
          </cylinder>
        </geometry>
        <surface>
          <friction>
            <ode>
              <mu>0.5</mu>
              <mu2>0.5</mu2>
            </ode>
          </friction>
          <contact>
            <ode>
              <kp>100000</kp>
              <kd>1</kd>
            </ode>
          </contact>
        </surface>
      </collision>
      <visual name="visual">
        <geometry>
          <cylinder>
            <radius>0.072</radius>
            <length>0.04</length>
          </cylinder>
        </geometry>
        <material>
          <script>
            <uri>file://media/materials/scripts/gazebo.material</uri>
            <name>Gazebo/Red</name>
          </script>
        </material>
      </visual>
    </link>

    <plugin name="differential_drive_controller" filename="libgazebo_ros_diff_drive.so">
      <commandTopic>/cmd_vel</commandTopic>
      <odometryTopic>/odom</odometryTopic>
      <odometryFrame>odom</odometryFrame>
      <robotBaseFrame>base_link</robotBaseFrame>
      <publishWheelTF>false</publishWheelTF>
      <publishOdomTF>true</publishOdomTF>
      <publishWheelJointState>false</publishWheelJointState>
      <wheelSeparation>0.36</wheelSeparation>
      <wheelDiameter>0.144</wheelDiameter>
      <wheelAcceleration>30</wheelAcceleration>
      <wheelTorque>5.0</wheelTorque>
      <updateRate>40</updateRate>
      <odometrySource>encoder</odometrySource>
      <leftJoint>left_wheel_joint</leftJoint>
      <rightJoint>right_wheel_joint</rightJoint>
      <publishTf>true</publishTf>
    </plugin>
  </model>
</sdf>
