<?xml version="1.0"?>
<robot name="my_robo" xmlns:xacro="http://ros.org/wiki/xacro">
  <material name="gray">
    <color rgba="0.5 0.5 0.5 2.5"/>
  </material>
  <material name="red">
    <color rgba="1.0 0.0 0.0 2.5"/>
  </material>

  <link name="/wheel_robot/base_link"/>

  <joint name="/wheel_robot/body_joint" type="fixed">
    <parent link="/wheel_robot/base_link"/>
    <child  link="/wheel_robot/body_link"/>
    <origin xyz="-0.08 0 0.07" rpy="0 0 0"/>
  </joint>
  <link name="/wheel_robot/body_link">
    <inertial>
      <origin xyz="0 0 0" rpy="0 0 0"/>
      <mass value="2.0"/>
      <inertia ixx="0.1" ixy="0.0" ixz="0.0" iyy="0.1" iyz="0.0" izz="0.1"/>
    </inertial>
    <visual>
      <origin xyz="0 0 0" rpy="0 0 0" />
      <geometry>
        <box size="0.24 0.19 0.06" />
      </geometry>
      <material name="gray" />
    </visual>
    <collision>
      <origin xyz="0 0 0" rpy="0 0 0"/>
      <geometry>
        <box size="0.23 0.18 0.05" />
      </geometry>
    </collision>
  </link>
  <gazebo reference="/wheel_robot/body_link">
    <mu1 value="0.5" />
    <mu2 value="0.5" />
    <material>Gazebo/Gray</material>
  </gazebo>

  <joint name="/wheel_robot/left_wheel_joint" type="continuous">
    <parent link="/wheel_robot/base_link"/>
    <child  link="/wheel_robot/left_wheel_link"/>
    <origin xyz="0 0.1 0.05" rpy="-1.5708 0 0"/>
    <axis xyz="0 0 1" />
    <limit velocity="20.0" effort="0.7" />
    <dynamics damping="0.1"/>
  </joint>
  <transmission name="/wheel_robot/left_wheel_trans">
    <type>transmission_interface/SimpleTransmission</type>
    <joint name="/wheel_robot/left_wheel_joint">
        <hardwareInterface>hardware_interface/VelocityJointInterface</hardwareInterface>
    </joint>
    <actuator name="/wheel_robot/left_wheel_motor">
       <hardwareInterface>hardware_interface/VelocityJointInterface</hardwareInterface>
       <mechanismReduction>1</mechanismReduction>
    </actuator>
  </transmission>

  <link name="/wheel_robot/left_wheel_link">
    <inertial>
      <origin xyz="0 0 0" rpy="0 0 0"/>
      <mass value="0.03"/>
      <inertia ixx="0.1" ixy="0.0" ixz="0.0" iyy="0.1" iyz="0.0" izz="0.1"/>
    </inertial>
    <visual>
      <origin xyz="0 0 0" rpy="0 0 0" />
      <geometry>
        <cylinder radius="0.05" length="0.01" />
      </geometry>
      <material name="red">
        <color rgba="0.5 0.5 0.5 2.5"/>
      </material>
    </visual>
    <collision>
      <origin xyz="0 0 0" rpy="0 0 0"/>
      <geometry>
        <cylinder radius="0.05" length="0.01" />
      </geometry>
    </collision>
  </link>
  <gazebo reference="/wheel_robot/left_wheel_link">
    <mu1 value="0.5" />
    <mu2 value="0.5" />
    <material>Gazebo/Red</material>
  </gazebo>

  <joint name="/wheel_robot/right_wheel_joint" type="continuous">
    <parent link="/wheel_robot/base_link"/>
    <child  link="/wheel_robot/right_wheel_link"/>
    <origin xyz="0 -0.1 0.05" rpy="-1.5708 0 0"/>
    <axis xyz="0 0 1" />
    <limit velocity="20.0" effort="0.7" />
    <dynamics damping="0.1"/>
  </joint>
  <transmission name="/wheel_robot/right_wheel_trans">
    <type>transmission_interface/SimpleTransmission</type>
    <joint name="/wheel_robot/right_wheel_joint">
        <hardwareInterface>hardware_interface/VelocityJointInterface</hardwareInterface>
    </joint>
    <actuator name="/wheel_robot/right_wheel_motor">
       <hardwareInterface>hardware_interface/VelocityJointInterface</hardwareInterface>
       <mechanismReduction>1</mechanismReduction>
    </actuator>
  </transmission>

  <link name="/wheel_robot/right_wheel_link">
    <inertial>
      <origin xyz="0 0 0" rpy="0 0 0"/>
      <mass value="0.03"/>
      <inertia ixx="0.1" ixy="0.0" ixz="0.0" iyy="0.1" iyz="0.0" izz="0.1"/>
    </inertial>
    <visual>
      <origin xyz="0 0 0" rpy="0 0 0" />
      <geometry>
        <cylinder radius="0.05" length="0.01" />
      </geometry>
      <material name="red">
        <color rgba="0.5 0.5 0.5 2.5"/>
      </material>
    </visual>
    <collision>
      <origin xyz="0 0 0" rpy="0 0 0"/>
      <geometry>
        <cylinder radius="0.05" length="0.01" />
      </geometry>
    </collision>
  </link>
  <gazebo reference="/wheel_robot/right_wheel_link">
    <mu1 value="0.5" />
    <mu2 value="0.5" />
    <material>Gazebo/Red</material>
  </gazebo>

  <joint name="/wheel_robot/rear_ball_joint" type="fixed">
    <parent link="/wheel_robot/base_link"/>
    <child  link="/wheel_robot/rear_ball_link"/>
    <origin xyz="-0.15 0 0.04" rpy="0 0 0"/>
    <axis xyz="0 0 1" />
  </joint>
  <link name="/wheel_robot/rear_ball_link">
    <inertial>
      <origin xyz="0 0 0" rpy="0 0 0"/>
      <mass value="0.1"/>
      <inertia ixx="0.1" ixy="0.0" ixz="0.0" iyy="0.1" iyz="0.0" izz="0.1"/>
    </inertial>
   <visual>
     <origin xyz="0 0 0" rpy="0 0 0" />
     <geometry>
       <sphere radius="0.04" />
     </geometry>
     <material name="gray" />
   </visual>
    <collision>
      <origin xyz="0 0 0" rpy="0 0 0"/>
      <geometry>
       <sphere radius="0.04" />
      </geometry>
    </collision>
  </link>
  <gazebo reference="/wheel_robot/rear_ball_link">
    <mu1 value="0.1" />
    <mu2 value="0.1" />
    <material>Gazebo/Gray</material>
  </gazebo>

  <joint name="/wheel_robot/lidar_joint" type="fixed">
    <parent link="/wheel_robot/body_link"/>
    <child  link="/wheel_robot/lidar_link"/>
    <origin xyz="0.09 0 0.05" rpy="0 0 0"/>
  </joint>
  <link name="/wheel_robot/lidar_link">
    <visual>
      <origin xyz="0 0 0" rpy="0 0 0" />
      <geometry>
        <cylinder radius="0.02" length="0.06" />
      </geometry>
      <material name="red" />
    </visual>
    <collision>
      <origin xyz="0 0 0" rpy="0 0 0"/>
      <geometry>
        <cylinder radius="0.02" length="0.06" />
      </geometry>
    </collision>
  </link>
  <gazebo reference="/wheel_robot/lidar_link">
    <material>Gazebo/Red</material>
    <sensor type="ray" name="head_lidar">
      <pose>0 0 0 0 0 0</pose>
      <visualize>false</visualize>
      <update_rate>10</update_rate>
      <ray>
        <scan>
          <horizontal>
            <samples>400</samples>
            <resolution>1</resolution>
            <min_angle>-3.141592</min_angle>
            <max_angle> 3.141592</max_angle>
          </horizontal>
        </scan>
        <range>
          <min>0.10</min>
          <max>20.0</max>
          <resolution>0.01</resolution>
        </range>
        <noise>
          <type>gaussian</type>
          <mean>0.0</mean>
          <stddev>0.01</stddev>
        </noise>
      </ray>
      <plugin name="gazebo_ros_lidar_controller" filename="libgazebo_ros_laser.so">
        <topicName>/wheel_robot/laser/scan</topicName>
        <frameName>wheel_robot/lidar_link</frameName>
      </plugin>
    </sensor>
  </gazebo>

  <gazebo reference="/wheel_robot/base_link">
    <gravity>true</gravity>
    <sensor name="imu_sensor" type="imu">
      <always_on>true</always_on>
      <update_rate>50</update_rate>
      <visualize>true</visualize>
      <topic>__default_topic__</topic>
      <plugin filename="libgazebo_ros_imu_sensor.so" name="imu_plugin">
        <topicName>/wheel_robot/imu/data</topicName>
        <bodyName>base_link</bodyName>
        <updateRateHZ>50.0</updateRateHZ>
        <gaussianNoise>0.00</gaussianNoise>
        <xyzOffset>0 0 0</xyzOffset>
        <rpyOffset>0 0 0</rpyOffset>
        <frameName>base_link</frameName>
      </plugin>
      <pose>0 0 0 0 0 0</pose>
    </sensor>
  </gazebo>  
  <gazebo>
    <plugin name="gazebo_ros_control" filename="libgazebo_ros_control.so">
      <robotNamespace>/wheel_robot</robotNamespace>
    </plugin>
  </gazebo>
</robot>
