<?xml version="1.0"?>
<robot name="my_robo" xmlns:xacro="http://ros.org/wiki/xacro">
  <material name="gray">
    <color rgba="0.5 0.5 0.5 2.5"/>
  </material>
  <material name="red">
    <color rgba="1.0 0.0 0.0 2.5"/>
  </material>

  <link name="base_link"/>

  <joint name="bodyjoint" type="fixed">
    <parent link="base_link"/>
    <child  link="body_link"/>
    <origin xyz="0.05 0 0.07" rpy="0 0 0"/>
  </joint>
  <link name="body_link">
    <inertial>
      <origin xyz="0 0 0" rpy="0 0 0"/>
      <mass value="2.0"/>
      <inertia ixx="0.1" ixy="0.0" ixz="0.0" iyy="0.1" iyz="0.0" izz="0.1"/>
    </inertial>
    <visual>
      <origin xyz="0 0 0" rpy="0 0 0" />
      <geometry>
        <box size="0.24 0.16 0.06" />
      </geometry>
      <material name="gray" />
    </visual>
    <collision>
      <origin xyz="0 0 0" rpy="0 0 0"/>
      <geometry>
        <box size="0.23 0.15 0.05" />
      </geometry>
    </collision>
  </link>
  <gazebo reference="body_link">
    <mu1 value="0.5" />
    <mu2 value="0.5" />
    <material>Gazebo/Gray</material>
  </gazebo>

  <joint name="left_wheel_joint" type="continuous">
    <parent link="base_link"/>
    <child  link="left_wheel_link"/>
    <origin xyz="0 0.1 0.05" rpy="-1.5708 0 0"/>
    <axis xyz="0 0 1" />
    <limit velocity="12.0" effort="0.4" />
    <dynamics damping="0.1"/>
  </joint>
  <transmission name="left_wheel_trans">
    <type>transmission_interface/SimpleTransmission</type>
    <joint name="left_wheel_joint">
        <hardwareInterface>hardware_interface/VelocityJointInterface</hardwareInterface>
    </joint>
    <actuator name="left_wheel_motor">
       <hardwareInterface>hardware_interface/VelocityJointInterface</hardwareInterface>
       <mechanismReduction>1</mechanismReduction>
    </actuator>
  </transmission>

  <link name="left_wheel_link">
    <inertial>
      <origin xyz="0 0 0" rpy="0 0 0"/>
      <mass value="0.1"/>
      <inertia ixx="0.1" ixy="0.0" ixz="0.0" iyy="0.1" iyz="0.0" izz="0.1"/>
    </inertial>
    <visual>
      <origin xyz="0 0 0" rpy="0 0 0" />
      <geometry>
        <cylinder radius="0.05" length="0.04" />
      </geometry>
      <material name="red">
        <color rgba="0.5 0.5 0.5 2.5"/>
      </material>
    </visual>
    <collision>
      <origin xyz="0 0 0" rpy="0 0 0"/>
      <geometry>
        <cylinder radius="0.05" length="0.04" />
      </geometry>
    </collision>
  </link>
  <gazebo reference="left_wheel_link">
    <mu1 value="0.5" />
    <mu2 value="0.5" />
    <material>Gazebo/Red</material>
  </gazebo>

  <joint name="right_wheel_joint" type="continuous">
    <parent link="base_link"/>
    <child  link="right_wheel_link"/>
    <origin xyz="0 -0.1 0.05" rpy="-1.5708 0 0"/>
    <axis xyz="0 0 1" />
    <limit velocity="12.0" effort="0.4" />
    <dynamics damping="0.1"/>
  </joint>
  <transmission name="right_wheel_trans">
    <type>transmission_interface/SimpleTransmission</type>
    <joint name="right_wheel_joint">
        <hardwareInterface>hardware_interface/VelocityJointInterface</hardwareInterface>
    </joint>
    <actuator name="right_wheel_motor">
       <hardwareInterface>hardware_interface/VelocityJointInterface</hardwareInterface>
       <mechanismReduction>1</mechanismReduction>
    </actuator>
  </transmission>

  <link name="right_wheel_link">
    <inertial>
      <origin xyz="0 0 0" rpy="0 0 0"/>
      <mass value="0.1"/>
      <inertia ixx="0.1" ixy="0.0" ixz="0.0" iyy="0.1" iyz="0.0" izz="0.1"/>
    </inertial>
    <visual>
      <origin xyz="0 0 0" rpy="0 0 0" />
      <geometry>
        <cylinder radius="0.05" length="0.04" />
      </geometry>
      <material name="red">
        <color rgba="0.5 0.5 0.5 2.5"/>
      </material>
    </visual>
    <collision>
      <origin xyz="0 0 0" rpy="0 0 0"/>
      <geometry>
        <cylinder radius="0.05" length="0.04" />
      </geometry>
    </collision>
  </link>
  <gazebo reference="right_wheel_link">
    <mu1 value="0.5" />
    <mu2 value="0.5" />
    <material>Gazebo/Red</material>
  </gazebo>

  <joint name="front_steer_joint" type="continuous">
    <parent link="base_link"/>
    <child  link="front_steer_link"/>
    <origin xyz="0.14 0 0.05" rpy="0 0 0"/>
    <axis xyz="0 0 1" />
    <dynamics damping="0.7"/>
  </joint>
  <transmission name="front_steer_trans">
    <type>transmission_interface/SimpleTransmission</type>
    <joint name="front_steer_joint">
        <hardwareInterface>hardware_interface/EffortJointInterface</hardwareInterface>
    </joint>
    <actuator name="front_steer_motor">
       <hardwareInterface>hardware_interface/EffortJointInterface</hardwareInterface>
       <mechanismReduction>1</mechanismReduction>
    </actuator>
  </transmission>

  <link name="front_steer_link">
    <inertial>
      <origin xyz="0 0 0" rpy="0 0 0"/>
      <mass value="0.1"/>
      <inertia ixx="0.1" ixy="0.0" ixz="0.0" iyy="0.1" iyz="0.0" izz="0.1"/>
    </inertial>
   <visual>
     <origin xyz="0 0 0" rpy="0 0 0" />
     <geometry>
       <cylinder radius="0.01" length="0.04" />
     </geometry>
     <material name="gray" />
   </visual>
  </link>

  <joint name="front_wheel_joint" type="continuous">
    <parent link="front_steer_link"/>
    <child  link="front_wheel_link"/>
    <origin xyz="-0.01 0 -0.035" rpy="1.5708 0 0"/>
    <axis xyz="0 0 1" />
  </joint>
  <transmission name="front_wheel_trans">
    <type>transmission_interface/SimpleTransmission</type>
    <joint name="front_wheel_joint">
        <hardwareInterface>hardware_interface/EffortJointInterface</hardwareInterface>
    </joint>
    <actuator name="front_wheel_motor">
       <hardwareInterface>hardware_interface/EffortJointInterface</hardwareInterface>
       <mechanismReduction>1</mechanismReduction>
    </actuator>
  </transmission>

  <link name="front_wheel_link">
    <inertial>
      <origin xyz="0 0 0" rpy="0 0 0"/>
      <mass value="0.3"/>
      <inertia ixx="0.1" ixy="0.0" ixz="0.0" iyy="0.1" iyz="0.0" izz="0.1"/>
    </inertial>
    <visual>
      <origin xyz="0 0 0" rpy="0 0 0" />
      <geometry>
        <cylinder radius="0.015" length="0.02" />
      </geometry>
      <material name="red" />
    </visual>
    <collision>
      <origin xyz="0 0 0" rpy="0 0 0"/>
      <geometry>
        <cylinder radius="0.015" length="0.02" />
      </geometry>
    </collision>
  </link>
  <gazebo reference="front_wheel_link">
    <mu1 value="1.3" />
    <mu2 value="1.3" />
    <material>Gazebo/Gray</material>
  </gazebo>

  <joint name="lidar_joint" type="fixed">
    <parent link="body_link"/>
    <child  link="lidar_link"/>
    <origin xyz="0.10 0 0.05" rpy="0 0 0"/>
  </joint>
  <link name="lidar_link">
    <visual>
      <origin xyz="0 0 0" rpy="0 0 0" />
      <geometry>
        <cylinder radius="0.02" length="0.06" />
      </geometry>
      <material name="red" />
    </visual>
    <collision>
      <origin xyz="0 0 0" rpy="0 0 0"/>
      <geometry>
        <cylinder radius="0.05" length="0.1" />
      </geometry>
    </collision>
  </link>
  <gazebo reference="lidar_link">
    <material>Gazebo/Red</material>
    <sensor type="ray" name="head_lidar">
      <pose>0 0 0 0 0 0</pose>
      <visualize>false</visualize>
      <update_rate>10</update_rate>
      <ray>
        <scan>
          <horizontal>
            <samples>400</samples>
            <resolution>1</resolution>
            <min_angle>-3.141592</min_angle>
            <max_angle> 3.141592</max_angle>
          </horizontal>
        </scan>
        <range>
          <min>0.10</min>
          <max>20.0</max>
          <resolution>0.01</resolution>
        </range>
        <noise>
          <type>gaussian</type>
          <mean>0.0</mean>
          <stddev>0.01</stddev>
        </noise>
      </ray>
      <plugin name="gazebo_ros_lidar_controller" filename="libgazebo_ros_laser.so">
        <topicName>/laser/scan</topicName>
        <frameName>lidar_link</frameName>
      </plugin>
    </sensor>
  </gazebo>

  <joint name="imu_joint" type="fixed">
    <parent link="body_link"/>
    <child  link="imu_link"/>
    <origin xyz="0 0 0" rpy="0 0 0"/>
  </joint>
  <link name="imu_link"/>
  <gazebo reference="imu_link">
    <gravity>true</gravity>
    <sensor name="imu_sensor" type="imu">
      <always_on>true</always_on>
      <update_rate>100</update_rate>
      <visualize>true</visualize>
      <topic>__default_topic__</topic>
      <plugin filename="libgazebo_ros_imu_sensor.so" name="imu_plugin">
        <topicName>imu</topicName>
        <bodyName>imu_link</bodyName>
        <updateRateHZ>10.0</updateRateHZ>
        <gaussianNoise>0.0</gaussianNoise>
        <xyzOffset>0 0 0</xyzOffset>
        <rpyOffset>0 0 0</rpyOffset>
        <frameName>imu_link</frameName>
      </plugin>
      <pose>0 0 0 0 0 0</pose>
    </sensor>
  </gazebo>

  <gazebo>
    <plugin name="gazebo_ros_control" filename="libgazebo_ros_control.so">
      <robotNamespace>/wheel_robot</robotNamespace>
    </plugin>
  </gazebo>
</robot>
