<?xml version="1.0"?>
<robot name="my_robo" xmlns:xacro="http://ros.org/wiki/xacro">
  <material name="gray">
    <color rgba="0.5 0.5 0.5 2.5"/>
  </material>
  <material name="red">
    <color rgba="1.0 0.0 0.0 2.5"/>
  </material>

  <link name="base_link"/>

  <joint name="bodyjoint" type="fixed">
    <parent link="base_link"/>
    <child  link="body_link"/>
    <origin xyz="0.05 0 0.07" rpy="0 0 0"/>
  </joint>
  <link name="body_link">
    <inertial>
      <origin xyz="0 0 0" rpy="0 0 0"/>
      <mass value="1.0"/>
      <inertia ixx="0.1" ixy="0.0" ixz="0.0" iyy="0.1" iyz="0.0" izz="0.1"/>
    </inertial>
    <visual>
      <origin xyz="0 0 0" rpy="0 0 0" />
      <geometry>
        <box size="0.24 0.16 0.06" />
      </geometry>
      <material name="gray" />
    </visual>
    <collision>
      <origin xyz="0 0 0" rpy="0 0 0"/>
      <geometry>
        <box size="0.23 0.15 0.05" />
      </geometry>
    </collision>
  </link>

  <joint name="left_wheel_joint" type="continuous">
    <parent link="base_link"/>
    <child  link="left_wheel_link"/>
    <origin xyz="0 0.1 0.05" rpy="-1.5708 0 0"/>
    <axis xyz="0 0 1" />
  </joint>
  <link name="left_wheel_link">
    <inertial>
      <origin xyz="0 0 0" rpy="0 0 0"/>
      <mass value="0.3"/>
      <inertia ixx="0.1" ixy="0.0" ixz="0.0" iyy="0.1" iyz="0.0" izz="0.1"/>
    </inertial>
    <visual>
      <origin xyz="0 0 0" rpy="0 0 0" />
      <geometry>
        <cylinder radius="0.05" length="0.04" />
      </geometry>
      <material name="red">
        <color rgba="0.5 0.5 0.5 2.5"/>
      </material>
    </visual>
    <collision>
      <origin xyz="0 0 0" rpy="0 0 0"/>
      <geometry>
        <cylinder radius="0.05" length="0.04" />
      </geometry>
    </collision>
  </link>

  <joint name="right_wheel_joint" type="continuous">
    <parent link="base_link"/>
    <child  link="right_wheel_link"/>
    <origin xyz="0 -0.1 0.05" rpy="1.5708 0 0"/>
    <axis xyz="0 0 1" />
  </joint>
  <link name="right_wheel_link">
    <inertial>
      <origin xyz="0 0 0" rpy="0 0 0"/>
      <mass value="0.3"/>
      <inertia ixx="0.1" ixy="0.0" ixz="0.0" iyy="0.1" iyz="0.0" izz="0.1"/>
    </inertial>
    <visual>
      <origin xyz="0 0 0" rpy="0 0 0" />
      <geometry>
        <cylinder radius="0.05" length="0.04" />
      </geometry>
      <material name="red">
        <color rgba="0.5 0.5 0.5 2.5"/>
      </material>
    </visual>
    <collision>
      <origin xyz="0 0 0" rpy="0 0 0"/>
      <geometry>
        <cylinder radius="0.05" length="0.04" />
      </geometry>
    </collision>
  </link>

  <joint name="front_steer_joint" type="continuous">
    <parent link="base_link"/>
    <child  link="front_steer_link"/>
    <origin xyz="0.14 0 0.05" rpy="0 0 0"/>
    <axis xyz="0 0 1" />
  </joint>
  <link name="front_steer_link">
    <inertial>
      <origin xyz="0 0 0" rpy="0 0 0"/>
      <mass value="0.1"/>
      <inertia ixx="0.1" ixy="0.0" ixz="0.0" iyy="0.1" iyz="0.0" izz="0.1"/>
    </inertial>
   <visual>
     <origin xyz="0 0 0" rpy="0 0 0" />
     <geometry>
       <cylinder radius="0.01" length="0.04" />
     </geometry>
     <material name="gray" />
   </visual>
  </link>

  <joint name="front_wheel_joint" type="continuous">
    <parent link="front_steer_link"/>
    <child  link="front_wheel_link"/>
    <origin xyz="-0.01 0 -0.035" rpy="1.5708 0 0"/>
    <axis xyz="0 0 1" />
  </joint>
  <link name="front_wheel_link">
    <inertial>
      <origin xyz="0 0 0" rpy="0 0 0"/>
      <mass value="0.3"/>
      <inertia ixx="0.1" ixy="0.0" ixz="0.0" iyy="0.1" iyz="0.0" izz="0.1"/>
    </inertial>
    <visual>
      <origin xyz="0 0 0" rpy="0 0 0" />
      <geometry>
        <cylinder radius="0.015" length="0.02" />
      </geometry>
      <material name="red" />
    </visual>
    <collision>
      <origin xyz="0 0 0" rpy="0 0 0"/>
      <geometry>
        <cylinder radius="0.015" length="0.02" />
      </geometry>
    </collision>
  </link>
</robot>
