<?xml version='1.0'?>
<sdf version="1.4">
  <model name="wheel_robot_sensor">
    <link name="body_link">
      <pose>-0.10 0 0.1 0 0 0</pose>
      <inertial>
        <mass>5.0</mass>
        <inertia>
          <ixx>0.042</ixx>
          <ixy>0.0</ixy>
          <ixz>0.0</ixz>
          <iyy>0.071</iyy>
          <iyz>0.0</iyz>
          <izz>0.104</izz>
        </inertia>
      </inertial>
      <collision name="collision">
        <geometry>
          <box>
            <size>0.4 0.3 0.1</size>
          </box>
        </geometry>
      </collision>
      <visual name="visual">
        <geometry>
          <box>
            <size>0.4 0.3 0.1</size>
          </box>
        </geometry>
      </visual>
    </link>

    <joint name='back_ball_joint' type='fixed'>
      <parent>body_link</parent>
      <child>back_ball_link</child>
      <pose>0 0 0 0 0 0</pose>
      <axis>
        <use_parent_model_frame>true</use_parent_model_frame>
        <xyz>-0.23 0 0.05</xyz>
      </axis>
    </joint>
    <link name="back_ball_link">
      <pose>-0.23 0 0.05 0 0 0</pose>
      <inertial>
        <mass>0.1</mass>
        <inertia>
          <ixx>0.0001</ixx>
          <ixy>0.0</ixy>
          <ixz>0.0</ixz>
          <iyy>0.0001</iyy>
          <iyz>0.0</iyz>
          <izz>0.0001</izz>
        </inertia>
      </inertial>
      <collision name="collision">
        <geometry>
          <sphere>
            <radius>0.05</radius>
          </sphere>
        </geometry>
        <surface>
          <friction>
            <ode>
              <mu>0.1</mu>
              <mu2>0.1</mu2>
            </ode>
          </friction>
          <contact>
            <ode>
              <kp>200000</kp>
              <kd>1</kd>
            </ode>
          </contact>
        </surface>
      </collision>
      <visual name="visual">
        <geometry>
          <sphere>
            <radius>0.05</radius>
          </sphere>
        </geometry>
      </visual>
    </link>

    <joint name='left_wheel_joint' type='revolute'>
      <parent>body_link</parent>
      <child>left_wheel_link</child>
      <pose>0 0 0 0 0 0</pose>
      <axis>
        <xyz>0 1 0</xyz>
      </axis>
    </joint>
    <link name="left_wheel_link">
      <pose>0 0.18 0.072 1.5707 0 0</pose>
      <inertial>
        <mass>0.2</mass>
        <inertia>
          <ixx>0.00026</ixx>
          <ixy>0.0</ixy>
          <ixz>0.0</ixz>
          <iyy>0.00026</iyy>
          <iyz>0.0</iyz>
          <izz>0.00052</izz>
        </inertia>
      </inertial>
      <collision name="collision">
        <geometry>
          <cylinder>
            <radius>0.072</radius>
            <length>0.04</length>
          </cylinder>
        </geometry>
        <surface>
          <friction>
            <ode>
              <mu>0.5</mu>
              <mu2>0.5</mu2>
            </ode>
          </friction>
          <contact>
            <ode>
              <kp>100000</kp>
              <kd>1</kd>
            </ode>
          </contact>
        </surface>
      </collision>
      <visual name="visual">
        <geometry>
          <cylinder>
            <radius>0.072</radius>
            <length>0.04</length>
          </cylinder>
        </geometry>
        <material>
          <script>
            <uri>file://media/materials/scripts/gazebo.material</uri>
            <name>Gazebo/Red</name>
          </script>
        </material>
      </visual>
    </link>

    <joint name='right_wheel_joint' type='revolute'>
      <parent>body_link</parent>
      <child>right_wheel_link</child>
      <pose>0 0 0 0 0 0</pose>
      <axis>
        <xyz>0 1 0</xyz>
      </axis>
    </joint>
    <link name="right_wheel_link">
      <pose>0 -0.18 0.072 1.5707 0 0</pose>
      <inertial>
        <mass>0.2</mass>
        <inertia>
          <ixx>0.00026</ixx>
          <ixy>0.0</ixy>
          <ixz>0.0</ixz>
          <iyy>0.00026</iyy>
          <iyz>0.0</iyz>
          <izz>0.00052</izz>
        </inertia>
      </inertial>
      <collision name="collision">
        <geometry>
          <cylinder>
            <radius>0.072</radius>
            <length>0.04</length>
          </cylinder>
        </geometry>
        <surface>
          <friction>
            <ode>
              <mu>0.5</mu>
              <mu2>0.5</mu2>
            </ode>
          </friction>
          <contact>
            <ode>
              <kp>100000</kp>
              <kd>1</kd>
            </ode>
          </contact>
        </surface>
      </collision>
      <visual name="visual">
        <geometry>
          <cylinder>
            <radius>0.072</radius>
            <length>0.04</length>
          </cylinder>
        </geometry>
        <material>
          <script>
            <uri>file://media/materials/scripts/gazebo.material</uri>
            <name>Gazebo/Red</name>
          </script>
        </material>
      </visual>
    </link>

    <plugin name="differential_drive_controller" filename="libgazebo_ros_diff_drive.so">
      <commandTopic>/cmd_vel</commandTopic>
      <odometryTopic>/odom</odometryTopic>
      <odometryFrame>odom</odometryFrame>
      <robotBaseFrame>base_link</robotBaseFrame>
      <publishWheelTF>false</publishWheelTF>
      <publishOdomTF>true</publishOdomTF>
      <publishWheelJointState>false</publishWheelJointState>
      <wheelSeparation>0.36</wheelSeparation>
      <wheelDiameter>0.144</wheelDiameter>
      <wheelAcceleration>30</wheelAcceleration>
      <wheelTorque>5.0</wheelTorque>
      <updateRate>40</updateRate>
      <odometrySource>encoder</odometrySource>
      <leftJoint>left_wheel_joint</leftJoint>
      <rightJoint>right_wheel_joint</rightJoint>
      <publishTf>true</publishTf>
    </plugin>

    <!-- sensors -->

    <joint name='front_laser_joint' type='fixed'>
      <parent>body_link</parent>
      <child>front_laser_link</child>
      <pose>0 0 0 0 0 0</pose>
    </joint>
    <link name="front_laser_link">
      <pose>0.05 0 0.17 0 0 0</pose>
      <inertial>
        <mass>0.1</mass>
        <inertia>
          <ixx>0.00026</ixx>
          <ixy>0.0</ixy>
          <ixz>0.0</ixz>
          <iyy>0.00026</iyy>
          <iyz>0.0</iyz>
          <izz>0.00045</izz>
        </inertia>
      </inertial>
      <collision name="collision">
        <geometry>
          <cylinder>
            <radius>0.03</radius>
            <length>0.02</length>
          </cylinder>
        </geometry>
      </collision>
      <visual name="visual">
        <geometry>
          <cylinder>
            <radius>0.03</radius>
            <length>0.02</length>
          </cylinder>
        </geometry>
        <material>
          <script>
            <uri>file://media/materials/scripts/gazebo.material</uri>
            <name>Gazebo/Blue</name>
          </script>
        </material>
      </visual>
      <sensor type="ray" name="front_laser">
        <always_on>true</always_on>
        <update_rate>10</update_rate>
        <visualize>true</visualize>
        <pose>0 0 0 0 0 0</pose>
        <ray>
          <scan>
            <horizontal>
              <samples>400</samples>
              <resolution>1</resolution>
              <min_angle>-3.1415</min_angle>
              <max_angle>3.1415</max_angle>
            </horizontal>
          </scan>
          <range>
            <min>0.05</min>
            <max>20.0</max>
            <resolution>0.01</resolution>
          </range>
          <noise>
            <type>gaussian</type>
            <mean>0.0</mean>
            <stddev>0.01</stddev>
          </noise>
        </ray>
        <plugin name="gazebo_ros_lidar_controller" filename="libgazebo_ros_laser.so">
          <topicName>/device/front_laser/scan</topicName>
          <frameName>front_laser_link</frameName>
        </plugin>
      </sensor>
    </link>

    <joint name='main_imu_joint' type='fixed'>
      <parent>body_link</parent>
      <child>main_imu_link</child>
      <pose>0 0 0 0 0 0</pose>
    </joint>
    <link name="main_imu_link">
      <pose>-0.10 0 0.15 0 0 0</pose>
      <inertial>
        <mass>0.05</mass>
        <inertia>
          <ixx>0.000033</ixx>
          <ixy>0.0</ixy>
          <ixz>0.0</ixz>
          <iyy>0.000033</iyy>
          <iyz>0.0</iyz>
          <izz>0.000033</izz>
        </inertia>
      </inertial>
      <collision name="collision">
        <geometry>
          <box>
            <size>0.02 0.02 0.02</size>
          </box>
        </geometry>
      </collision>
      <visual name="visual">
        <geometry>
          <box>
            <size>0.02 0.02 0.02</size>
          </box>
        </geometry>
        <material>
          <script>
            <uri>file://media/materials/scripts/gazebo.material</uri>
            <name>Gazebo/Blue</name>
          </script>
        </material>
      </visual>

      <gravity>true</gravity>
      <sensor name="main_imu" type="imu">
        <always_on>true</always_on>
        <update_rate>20</update_rate>
        <visualize>true</visualize>
        <plugin filename="libgazebo_ros_imu_sensor.so" name="imu_plugin">
          <topicName>/main_imu/data</topicName>
          <bodyName>main_imu_link</bodyName>
          <updateRateHZ>10.0</updateRateHZ>
          <gaussianNoise>0.0</gaussianNoise>
          <xyzOffset>0 0 0</xyzOffset>
          <rpyOffset>0 0 0</rpyOffset>
          <frameName>main_imu_link</frameName>
          <initialOrientationAsReference>false</initialOrientationAsReference>
        </plugin>
        <pose>0 0 0 0 0 0</pose>
      </sensor>
    </link>

    <joint name='head_camera_joint' type='fixed'>
      <parent>body_link</parent>
      <child>head_camera_link</child>
      <pose>0 0 0 0 0 0</pose>
    </joint>
    <link name="head_camera_link">
      <pose>0 0 0.25 0 0 0</pose>
      <inertial>
        <mass>0.05</mass>
        <inertia>
          <ixx>0.00012</ixx>
          <ixy>0.0</ixy>
          <ixz>0.0</ixz>
          <iyy>0.000021</iyy>
          <iyz>0.0</iyz>
          <izz>0.00011</izz>
        </inertia>
      </inertial>
      <collision name="collision">
        <geometry>
          <box>
            <size>0.01 0.05 0.02</size>
          </box>
        </geometry>
      </collision>
      <visual name="visual">
        <geometry>
          <box>
            <size>0.01 0.05 0.02</size>
          </box>
        </geometry>
        <material>
          <script>
            <uri>file://media/materials/scripts/gazebo.material</uri>
            <name>Gazebo/Blue</name>
          </script>
        </material>
      </visual>

      <sensor type="camera" name="head_camera">
        <always_on>true</always_on>
        <update_rate>20</update_rate>
        <visualize>true</visualize>
        <camera name="head_camera">
          <horizontal_fov>1.2</horizontal_fov>
          <image>
            <width>800</width>
            <height>600</height>
            <format>R8G8B8</format>
          </image>
          <clip>
            <near>0.02</near>
            <far>300</far>
          </clip>
          <noise>
            <type>gaussian</type>
            <mean>0.0</mean>
            <stddev>0.007</stddev>
          </noise>
          <distortion>
            <k1>-0.25</k1>
            <k2>0.12</k2>
            <k3>0.0</k3>
            <p1>0.0</p1>
            <p2>0.0</p2>
            <center>0.5 0.5</center>
          </distortion>
        </camera>
        <plugin name="camera_controller" filename="libgazebo_ros_camera.so">
          <imageTopicName>/head_camera/image_raw</imageTopicName>
          <cameraInfoTopicName>/head_camera/camera_info</cameraInfoTopicName>
          <cameraName>camera1</cameraName>
          <frameName>head_camera_link</frameName>
          <updateRate>10.0</updateRate>
          <CxPrime>0.0</CxPrime>
          <Cx>0.0</Cx>
          <Cy>0.0</Cy>
          <focalLength>-0.25</focalLength>
          <hackBaseline>0.12</hackBaseline>
          <distortionK1>0.05</distortionK1>
          <distortionK2>-0.05</distortionK2>
          <distortionK3>0.0</distortionK3>
          <distortionT1>0.0</distortionT1>
          <distortionT2>0.0</distortionT2>
        </plugin>
      </sensor>
    </link>
  </model>
</sdf>
